Workbook

Sheet Assignment

Sheet Q1
B3: Q1. Explain the difference between Relative , Absolute and Mixed Cell Referencing. you have the following dataset.
C5: Vehicle | D5: Price
C6: Car | D6: 500000
C7: Bi-cycle | D7: 10500
C8: Auto-Rickshaw | D8: 25000
C11: Relative Cell reference:-
D12: A relative cell reference is a cell reference in excel that changes automatically when a formula is copied or moved to another cell
D13: basically it mean it adjust itself according to the position of the formula
D14: let's take an example. I have simply just added another column lets assume discount is 10% for every product
D15: Vehicle | E15: Price | F15: Price after Discount
D16: Car | E16: 500000 | F16: ='Q1'!$E16*0.9 -> 450000
D17: Bi-cycle | E17: 10500 | F17: ='Q1'!$E17*0.9 -> 9450
D18: Auto-Rickshaw | E18: 25000 | F18: ='Q1'!$E18*0.9 -> 22500
D20: Price after adjusted itself and gave price after discount using information form other columns
C23: Absolute Cell reference:-
D24: An absolute cell reference is a cell reference that does not does not change when a formula is moved or copied to another cell
D25: in short, the cell address is fixed and stays same every time
D26: let's take an example I have student data with their total grades and maximum marks (100) we will find percenatge of each student using absolute cell
D27: Student | E27: Marks | F27: Percentage
D28: Max Score | E28: 100
D29: Abhijeet | E29: 75 | F29: ='Q1'!$E29/$E$28 -> 0.75
D30: Akshay | E30: 92 | F30: ='Q1'!$E30/$E$28 -> 0.92
D31: rahul | E31: 88 | F31: ='Q1'!$E31/$E$28 -> 0.88
D32: Ajay | E32: 68 | F32: ='Q1'!$E32/$E$28 -> 0.68
D34: using shortcut key(F4), I have locked cell E28 where max score located(100) I calculated all the percenatges of students
C37: Mixed Cell reference:-
D38: A mixed cell reference is a cell reference in excel where only one part changes either the row or the coloumn while other part remain fixed
D39: in short, its is mixture of relative and absolute referencing, half fixed , half changed.
E40: let's take an example of a multiplication table with rows and coloums calculation
D43: Multiplication table
E45: Column Headers
E47: 1 | F47: 2 | G47: 3 | H47: 4 | I47: 5
D48: 10 | E48: =$D48*E$47 -> 10 | F48: =$D48*F$47 -> 20 | G48: =$D48*G$47 -> 30 | H48: =$D48*H$47 -> 40 | I48: =$D48*I$47 -> 50
D49: 20 | E49: =$D49*E$47 -> 20 | F49: =$D49*F$47 -> 40 | G49: =$D49*G$47 -> 60 | H49: =$D49*H$47 -> 80 | I49: =$D49*I$47 -> 100
D50: 30 | E50: =$D50*E$47 -> 30 | F50: =$D50*F$47 -> 60 | G50: =$D50*G$47 -> 90 | H50: =$D50*H$47 -> 120 | I50: =$D50*I$47 -> 150
D51: 40 | E51: =$D51*E$47 -> 40 | F51: =$D51*F$47 -> 80 | G51: =$D51*G$47 -> 120 | H51: =$D51*H$47 -> 160 | I51: =$D51*I$47 -> 200
D52: 50 | E52: =$D52*E$47 -> 50 | F52: =$D52*F$47 -> 100 | G52: =$D52*G$47 -> 150 | H52: =$D52*H$47 -> 200 | I52: =$D52*I$47 -> 250
D54: here I have locked formula using f4 , where all the rows are locked and we are just moving woth columns as you can see in formula
D55: I have shown this in a formula format just for an understanding of cell referecnes

Sheet Q2
B3: Q2.Write a formula to calculate the total sales of Car and Bicyle only.
G5: USING SUM
C6: Vehicle | D6: Price | G6: Vehicle | H6: Price | K6: Vehicle | L6: Price
C7: Car | D7: 500000 | G7: Car | H7: 500000 | K7: Car | L7: 500000
C8: Bi-cycle | D8: 10500 | G8: Bi-cycle | H8: 10500 | K8: Bi-cycle | L8: 10500
C9: Auto-Rickshaw | D9: 25000 | G9: Total Sales | H9: =SUM(H7:H8) -> 510500 | K9: using SUMIF
K10: =SUMIF(K7,"Car",L7)+SUMIF(K8,"Bi-cycle",L8) -> 510500

Sheet Q3
B2: Q3. Using the data below, write a formula to calculate the average sales of items priced above 100 but less than 300:
B6: Item | C6: Price | D6: Sales
B7: Item A | C7: 90 | D7: 1000
B8: Item B | C8: 150 | D8: 1200
B9: Item c | C9: 250 | D9: 1500
B13: so the valid prices are 150 & 250 and their respective sales
B14: First method using average formula
B16: =AVERAGE(D8:D9) -> 1350 | D16: formula used = AVERAGE(D8:D9)
B19: Second method using AverageIF function
B23: Item | C23: Price | D23: Sales
B24: Item B | C24: 150 | D24: 1200
B25: Item c | C25: 250 | D25: 1500
B28: =AVERAGEIFS(D24:D25,C24:C25, ">100",C24:C25,"<300") -> 1350 | D28: formula used =AVERAGEIFS(D24:D25,C24:C25, ">100",C24:C25,"<300")
B32: Average sales for items above 100 and below 300 is 1350

Sheet Sales data
B2: Use the following Dataset and solve the following questions.
B6: OrderID | C6: CustomerName | D6: Region | E6: Product | F6: Quantity | G6: UnitPrice | H6: OrderDate
B7: 1001 | C7: Amit Sharma | D7: North | E7: Notebook | F7: 10 | G7: 50 | H7: 45413
B8: 1002 | C8: Neha Verma | D8: South | E8: Pen | F8: 20 | G8: 10 | H8: 45444
B9: 1003 | C9: Rahul Singh | D9: East | E9: Marker | F9: 15 | G9: 25 | H9: 45474
B10: 1004 | C10: Pooja Mehta | D10: West | E10: Notebook | F10: 5 | G10: 50 | H10: 45505
B11: 1005 | C11: Ankit Jain | D11: North | E11: Pencil | F11: 30 | G11: 5 | H11: 45566
B12: 1006 | C12: Sneha Patel | D12: South | E12: Notebook | F12: 12 | G12: 50 | H12: 45597
B13: 1007 | C13: Vikas Gupta | D13: East | E13: Eraser | F13: 25 | G13: 8 | H13: 13-01-2024
B14: 1008 | C14: Meera Nair | D14: West | E14: Pen | F14: 18 | G14: 10 | H14: 15-01-2024
B15: 1009 | C15: Anjali Rao | D15: North | E15: Marker | F15: 22 | G15: 25 | H15: 17-01-2024
B16: 1010 | C16: Manoj Das | D16: South | E16: Notebook | F16: 8 | G16: 50 | H16: 18-01-2024
B17: 1011 | C17: Ritika Sen | D17: East | E17: Pencil | F17: 40 | G17: 5 | H17: 19-01-2024
B18: 1012 | C18: Karan Malhotra | D18: West | E18: Eraser | F18: 35 | G18: 8 | H18: 20-01-2024
B19: 1013 | C19: Aryan Joshi | D19: North | E19: Notebook | F19: 14 | G19: 50 | H19: 22-01-2024
B20: 1014 | C20: Divya Kapoor | D20: South | E20: Pen | F20: 28 | G20: 10 | H20: 23-01-2024
B21: 1015 | C21: Sahil Arora | D21: East | E21: Marker | F21: 12 | G21: 25 | H21: 24-01-2024
B22: 1016 | C22: Muskan Jain | D22: West | E22: Pencil | F22: 25 | G22: 5 | H22: 26-01-2024
B23: 1017 | C23: Rohan Gupta | D23: North | E23: Eraser | F23: 20 | G23: 8 | H23: 28-01-2024
B24: 1018 | C24: Nidhi Sharma | D24: South | E24: Notebook | F24: 10 | G24: 50 | H24: 29-01-2024
B25: 1019 | C25: Tarun Verma | D25: East | E25: Pen | F25: 15 | G25: 10 | H25: 30-01-2024
B26: 1020 | C26: Simran Kaur | D26: West | E26: Marker | F26: 18 | G26: 25 | H26: 45293
B27: 1021 | C27: Deepak Rao | D27: North | E27: Notebook | F27: 9 | G27: 50 | H27: 45324
B28: 1022 | C28: Payal Mehta | D28: South | E28: Pencil | F28: 35 | G28: 5 | H28: 45353
B29: 1023 | C29: Aditya Singh | D29: East | E29: Eraser | F29: 30 | G29: 8 | H29: 45384
B30: 1024 | C30: Shreya Nair | D30: West | E30: Notebook | F30: 11 | G30: 50 | H30: 45445
B31: 1025 | C31: Sanjay Kumar | D31: North | E31: Pen | F31: 14 | G31: 10 | H31: 45475
B32: 1026 | C32: Aarti Sharma | D32: South | E32: Marker | F32: 16 | G32: 25 | H32: 45506
B33: 1027 | C33: Rajesh Patel | D33: East | E33: Pencil | F33: 22 | G33: 5 | H33: 45537
B34: 1028 | C34: Preeti Joshi | D34: West | E34: Eraser | F34: 27 | G34: 8 | H34: 45567
B35: 1029 | C35: Anurag Mishra | D35: North | E35: Notebook | F35: 13 | G35: 50 | H35: 45628
B36: 1030 | C36: Sanya Kapoor | D36: South | E36: Pen | F36: 32 | G36: 10 | H36: 13-02-2024
B37: 1031 | C37: Harsh Yadav | D37: East | E37: Marker | F37: 10 | G37: 25 | H37: 14-02-2024
B38: 1032 | C38: Kajal Rani | D38: West | E38: Pencil | F38: 18 | G38: 5 | H38: 16-02-2024
B39: 1033 | C39: Varun Sharma | D39: North | E39: Eraser | F39: 22 | G39: 8 | H39: 17-02-2024
B40: 1034 | C40: Swati Arora | D40: South | E40: Notebook | F40: 17 | G40: 50 | H40: 18-02-2024
B41: 1035 | C41: Akhil Jain | D41: East | E41: Pen | F41: 19 | G41: 10 | H41: 19-02-2024
B42: 1036 | C42: Priyanka Das | D42: West | E42: Marker | F42: 15 | G42: 25 | H42: 21-02-2024
B43: 1037 | C43: Ravi Nair | D43: North | E43: Pencil | F43: 28 | G43: 5 | H43: 22-02-2024
B44: 1038 | C44: Komal Singh | D44: South | E44: Eraser | F44: 24 | G44: 8 | H44: 23-02-2024
...

Sheet Q4
A1: Count how many customer names are recorded.
B6: OrderID | C6: CustomerName | D6: Region | E6: Product | F6: Quantity | G6: UnitPrice | H6: OrderDate
B7: 1001 | C7: Amit Sharma | D7: North | E7: Notebook | F7: 10 | G7: 50 | H7: 45413
B8: 1002 | C8: Neha Verma | D8: South | E8: Pen | F8: 20 | G8: 10 | H8: 45444 | J8: Ans:
B9: 1003 | C9: Rahul Singh | D9: East | E9: Marker | F9: 15 | G9: 25 | H9: 45474 | J9: =COUNTA('Q4'!$C$7:$C$56) -> 50 | K9: using COUNTA we can calculate numbers of names present since it can take text values along with numbers,dates
B10: 1004 | C10: Pooja Mehta | D10: West | E10: Notebook | F10: 5 | G10: 50 | H10: 45505
B11: 1005 | C11: Ankit Jain | D11: North | E11: Pencil | F11: 30 | G11: 5 | H11: 45566
B12: 1006 | C12: Sneha Patel | D12: South | E12: Notebook | F12: 12 | G12: 50 | H12: 45597
B13: 1007 | C13: Vikas Gupta | D13: East | E13: Eraser | F13: 25 | G13: 8 | H13: 13-01-2024
B14: 1008 | C14: Meera Nair | D14: West | E14: Pen | F14: 18 | G14: 10 | H14: 15-01-2024
B15: 1009 | C15: Anjali Rao | D15: North | E15: Marker | F15: 22 | G15: 25 | H15: 17-01-2024
B16: 1010 | C16: Manoj Das | D16: South | E16: Notebook | F16: 8 | G16: 50 | H16: 18-01-2024
B17: 1011 | C17: Ritika Sen | D17: East | E17: Pencil | F17: 40 | G17: 5 | H17: 19-01-2024
B18: 1012 | C18: Karan Malhotra | D18: West | E18: Eraser | F18: 35 | G18: 8 | H18: 20-01-2024
B19: 1013 | C19: Aryan Joshi | D19: North | E19: Notebook | F19: 14 | G19: 50 | H19: 22-01-2024
B20: 1014 | C20: Divya Kapoor | D20: South | E20: Pen | F20: 28 | G20: 10 | H20: 23-01-2024
B21: 1015 | C21: Sahil Arora | D21: East | E21: Marker | F21: 12 | G21: 25 | H21: 24-01-2024
B22: 1016 | C22: Muskan Jain | D22: West | E22: Pencil | F22: 25 | G22: 5 | H22: 26-01-2024
B23: 1017 | C23: Rohan Gupta | D23: North | E23: Eraser | F23: 20 | G23: 8 | H23: 28-01-2024
B24: 1018 | C24: Nidhi Sharma | D24: South | E24: Notebook | F24: 10 | G24: 50 | H24: 29-01-2024
B25: 1019 | C25: Tarun Verma | D25: East | E25: Pen | F25: 15 | G25: 10 | H25: 30-01-2024
B26: 1020 | C26: Simran Kaur | D26: West | E26: Marker | F26: 18 | G26: 25 | H26: 45293
B27: 1021 | C27: Deepak Rao | D27: North | E27: Notebook | F27: 9 | G27: 50 | H27: 45324
B28: 1022 | C28: Payal Mehta | D28: South | E28: Pencil | F28: 35 | G28: 5 | H28: 45353
B29: 1023 | C29: Aditya Singh | D29: East | E29: Eraser | F29: 30 | G29: 8 | H29: 45384
B30: 1024 | C30: Shreya Nair | D30: West | E30: Notebook | F30: 11 | G30: 50 | H30: 45445
B31: 1025 | C31: Sanjay Kumar | D31: North | E31: Pen | F31: 14 | G31: 10 | H31: 45475
B32: 1026 | C32: Aarti Sharma | D32: South | E32: Marker | F32: 16 | G32: 25 | H32: 45506
B33: 1027 | C33: Rajesh Patel | D33: East | E33: Pencil | F33: 22 | G33: 5 | H33: 45537
B34: 1028 | C34: Preeti Joshi | D34: West | E34: Eraser | F34: 27 | G34: 8 | H34: 45567
B35: 1029 | C35: Anurag Mishra | D35: North | E35: Notebook | F35: 13 | G35: 50 | H35: 45628
B36: 1030 | C36: Sanya Kapoor | D36: South | E36: Pen | F36: 32 | G36: 10 | H36: 13-02-2024
B37: 1031 | C37: Harsh Yadav | D37: East | E37: Marker | F37: 10 | G37: 25 | H37: 14-02-2024
B38: 1032 | C38: Kajal Rani | D38: West | E38: Pencil | F38: 18 | G38: 5 | H38: 16-02-2024
B39: 1033 | C39: Varun Sharma | D39: North | E39: Eraser | F39: 22 | G39: 8 | H39: 17-02-2024
B40: 1034 | C40: Swati Arora | D40: South | E40: Notebook | F40: 17 | G40: 50 | H40: 18-02-2024
B41: 1035 | C41: Akhil Jain | D41: East | E41: Pen | F41: 19 | G41: 10 | H41: 19-02-2024
B42: 1036 | C42: Priyanka Das | D42: West | E42: Marker | F42: 15 | G42: 25 | H42: 21-02-2024
B43: 1037 | C43: Ravi Nair | D43: North | E43: Pencil | F43: 28 | G43: 5 | H43: 22-02-2024
B44: 1038 | C44: Komal Singh | D44: South | E44: Eraser | F44: 24 | G44: 8 | H44: 23-02-2024
...

Sheet Q5
B2: Calculate the Total Sales for each row using a formula.
B6: OrderID | C6: CustomerName | D6: Region | E6: Product | F6: Quantity | G6: UnitPrice | H6: Total Sales | I6: OrderDate
B7: 1001 | C7: Amit Sharma | D7: North | E7: Notebook | F7: 10 | G7: 50 | H7: =PRODUCT('Q5'!$F7*'Q5'!$G7) -> 500 | I7: 45413
B8: 1002 | C8: Neha Verma | D8: South | E8: Pen | F8: 20 | G8: 10 | H8: =PRODUCT('Q5'!$F8*'Q5'!$G8) -> 200 | I8: 45444
B9: 1003 | C9: Rahul Singh | D9: East | E9: Marker | F9: 15 | G9: 25 | H9: =PRODUCT('Q5'!$F9*'Q5'!$G9) -> 375 | I9: 45474
B10: 1004 | C10: Pooja Mehta | D10: West | E10: Notebook | F10: 5 | G10: 50 | H10: =PRODUCT('Q5'!$F10*'Q5'!$G10) -> 250 | I10: 45505 | K10: TOTAL SALES
B11: 1005 | C11: Ankit Jain | D11: North | E11: Pencil | F11: 30 | G11: 5 | H11: =PRODUCT('Q5'!$F11*'Q5'!$G11) -> 150 | I11: 45566
B12: 1006 | C12: Sneha Patel | D12: South | E12: Notebook | F12: 12 | G12: 50 | H12: =PRODUCT('Q5'!$F12*'Q5'!$G12) -> 600 | I12: 45597 | K12: First , I have added extra column total sales since SALES = (QTY*PRICE)
B13: 1007 | C13: Vikas Gupta | D13: East | E13: Eraser | F13: 25 | G13: 8 | H13: =PRODUCT('Q5'!$F13*'Q5'!$G13) -> 200 | I13: 13-01-2024 | K13: USING FORMULA = PRODUCT([@Quantity]*[@UnitPrice])
B14: 1008 | C14: Meera Nair | D14: West | E14: Pen | F14: 18 | G14: 10 | H14: =PRODUCT('Q5'!$F14*'Q5'!$G14) -> 180 | I14: 15-01-2024
B15: 1009 | C15: Anjali Rao | D15: North | E15: Marker | F15: 22 | G15: 25 | H15: =PRODUCT('Q5'!$F15*'Q5'!$G15) -> 550 | I15: 17-01-2024 | K15: now by taking all sum of all total sales values we can calculate total sales
B16: 1010 | C16: Manoj Das | D16: South | E16: Notebook | F16: 8 | G16: 50 | H16: =PRODUCT('Q5'!$F16*'Q5'!$G16) -> 400 | I16: 18-01-2024 | K16: =SUM('Q5'!$H$7:$H$56) -> 16543
B17: 1011 | C17: Ritika Sen | D17: East | E17: Pencil | F17: 40 | G17: 5 | H17: =PRODUCT('Q5'!$F17*'Q5'!$G17) -> 200 | I17: 19-01-2024
B18: 1012 | C18: Karan Malhotra | D18: West | E18: Eraser | F18: 35 | G18: 8 | H18: =PRODUCT('Q5'!$F18*'Q5'!$G18) -> 280 | I18: 20-01-2024
B19: 1013 | C19: Aryan Joshi | D19: North | E19: Notebook | F19: 14 | G19: 50 | H19: =PRODUCT('Q5'!$F19*'Q5'!$G19) -> 700 | I19: 22-01-2024
B20: 1014 | C20: Divya Kapoor | D20: South | E20: Pen | F20: 28 | G20: 10 | H20: =PRODUCT('Q5'!$F20*'Q5'!$G20) -> 280 | I20: 23-01-2024
B21: 1015 | C21: Sahil Arora | D21: East | E21: Marker | F21: 12 | G21: 25 | H21: =PRODUCT('Q5'!$F21*'Q5'!$G21) -> 300 | I21: 24-01-2024
B22: 1016 | C22: Muskan Jain | D22: West | E22: Pencil | F22: 25 | G22: 5 | H22: =PRODUCT('Q5'!$F22*'Q5'!$G22) -> 125 | I22: 26-01-2024
B23: 1017 | C23: Rohan Gupta | D23: North | E23: Eraser | F23: 20 | G23: 8 | H23: =PRODUCT('Q5'!$F23*'Q5'!$G23) -> 160 | I23: 28-01-2024
B24: 1018 | C24: Nidhi Sharma | D24: South | E24: Notebook | F24: 10 | G24: 50 | H24: =PRODUCT('Q5'!$F24*'Q5'!$G24) -> 500 | I24: 29-01-2024
B25: 1019 | C25: Tarun Verma | D25: East | E25: Pen | F25: 15 | G25: 10 | H25: =PRODUCT('Q5'!$F25*'Q5'!$G25) -> 150 | I25: 30-01-2024
B26: 1020 | C26: Simran Kaur | D26: West | E26: Marker | F26: 18 | G26: 25 | H26: =PRODUCT('Q5'!$F26*'Q5'!$G26) -> 450 | I26: 45293
B27: 1021 | C27: Deepak Rao | D27: North | E27: Notebook | F27: 9 | G27: 50 | H27: =PRODUCT('Q5'!$F27*'Q5'!$G27) -> 450 | I27: 45324
B28: 1022 | C28: Payal Mehta | D28: South | E28: Pencil | F28: 35 | G28: 5 | H28: =PRODUCT('Q5'!$F28*'Q5'!$G28) -> 175 | I28: 45353
B29: 1023 | C29: Aditya Singh | D29: East | E29: Eraser | F29: 30 | G29: 8 | H29: =PRODUCT('Q5'!$F29*'Q5'!$G29) -> 240 | I29: 45384
B30: 1024 | C30: Shreya Nair | D30: West | E30: Notebook | F30: 11 | G30: 50 | H30: =PRODUCT('Q5'!$F30*'Q5'!$G30) -> 550 | I30: 45445
B31: 1025 | C31: Sanjay Kumar | D31: North | E31: Pen | F31: 14 | G31: 10 | H31: =PRODUCT('Q5'!$F31*'Q5'!$G31) -> 140 | I31: 45475
B32: 1026 | C32: Aarti Sharma | D32: South | E32: Marker | F32: 16 | G32: 25 | H32: =PRODUCT('Q5'!$F32*'Q5'!$G32) -> 400 | I32: 45506
B33: 1027 | C33: Rajesh Patel | D33: East | E33: Pencil | F33: 22 | G33: 5 | H33: =PRODUCT('Q5'!$F33*'Q5'!$G33) -> 110 | I33: 45537
B34: 1028 | C34: Preeti Joshi | D34: West | E34: Eraser | F34: 27 | G34: 8 | H34: =PRODUCT('Q5'!$F34*'Q5'!$G34) -> 216 | I34: 45567
B35: 1029 | C35: Anurag Mishra | D35: North | E35: Notebook | F35: 13 | G35: 50 | H35: =PRODUCT('Q5'!$F35*'Q5'!$G35) -> 650 | I35: 45628
B36: 1030 | C36: Sanya Kapoor | D36: South | E36: Pen | F36: 32 | G36: 10 | H36: =PRODUCT('Q5'!$F36*'Q5'!$G36) -> 320 | I36: 13-02-2024
B37: 1031 | C37: Harsh Yadav | D37: East | E37: Marker | F37: 10 | G37: 25 | H37: =PRODUCT('Q5'!$F37*'Q5'!$G37) -> 250 | I37: 14-02-2024
B38: 1032 | C38: Kajal Rani | D38: West | E38: Pencil | F38: 18 | G38: 5 | H38: =PRODUCT('Q5'!$F38*'Q5'!$G38) -> 90 | I38: 16-02-2024
B39: 1033 | C39: Varun Sharma | D39: North | E39: Eraser | F39: 22 | G39: 8 | H39: =PRODUCT('Q5'!$F39*'Q5'!$G39) -> 176 | I39: 17-02-2024
B40: 1034 | C40: Swati Arora | D40: South | E40: Notebook | F40: 17 | G40: 50 | H40: =PRODUCT('Q5'!$F40*'Q5'!$G40) -> 850 | I40: 18-02-2024
B41: 1035 | C41: Akhil Jain | D41: East | E41: Pen | F41: 19 | G41: 10 | H41: =PRODUCT('Q5'!$F41*'Q5'!$G41) -> 190 | I41: 19-02-2024
B42: 1036 | C42: Priyanka Das | D42: West | E42: Marker | F42: 15 | G42: 25 | H42: =PRODUCT('Q5'!$F42*'Q5'!$G42) -> 375 | I42: 21-02-2024
B43: 1037 | C43: Ravi Nair | D43: North | E43: Pencil | F43: 28 | G43: 5 | H43: =PRODUCT('Q5'!$F43*'Q5'!$G43) -> 140 | I43: 22-02-2024
B44: 1038 | C44: Komal Singh | D44: South | E44: Eraser | F44: 24 | G44: 8 | H44: =PRODUCT('Q5'!$F44*'Q5'!$G44) -> 192 | I44: 23-02-2024
...

Sheet Q6
B2: Calculate the total sales of Notebooks in the North region only.
B6: OrderID | C6: CustomerName | D6: Region | E6: Product | F6: Quantity | G6: UnitPrice | H6: Total Sales | I6: OrderDate
B7: 1001 | C7: Amit Sharma | D7: North | E7: Notebook | F7: 10 | G7: 50 | H7: =PRODUCT('Q6'!$F7*'Q6'!$G7) -> 500 | I7: 45413 | K7: =SUMIFS('Q6'!$H$7:$H$56,'Q6'!$E$7:$E$56,"Notebook",'Q6'!$D$7:$D$56,"North") -> 2900
B8: 1002 | C8: Neha Verma | D8: South | E8: Pen | F8: 20 | G8: 10 | H8: =PRODUCT('Q6'!$F8*'Q6'!$G8) -> 200 | I8: 45444 | K8: using sumif formula, we used range and criteria of both region and product
B9: 1003 | C9: Rahul Singh | D9: East | E9: Marker | F9: 15 | G9: 25 | H9: =PRODUCT('Q6'!$F9*'Q6'!$G9) -> 375 | I9: 45474 | K9: SUMIFS(Table68910[Total Sales],Table68910[Product],"Notebook",Table68910[Region],"North")
B10: 1004 | C10: Pooja Mehta | D10: West | E10: Notebook | F10: 5 | G10: 50 | H10: =PRODUCT('Q6'!$F10*'Q6'!$G10) -> 250 | I10: 45505
B11: 1005 | C11: Ankit Jain | D11: North | E11: Pencil | F11: 30 | G11: 5 | H11: =PRODUCT('Q6'!$F11*'Q6'!$G11) -> 150 | I11: 45566
B12: 1006 | C12: Sneha Patel | D12: South | E12: Notebook | F12: 12 | G12: 50 | H12: =PRODUCT('Q6'!$F12*'Q6'!$G12) -> 600 | I12: 45597
B13: 1007 | C13: Vikas Gupta | D13: East | E13: Eraser | F13: 25 | G13: 8 | H13: =PRODUCT('Q6'!$F13*'Q6'!$G13) -> 200 | I13: 13-01-2024
B14: 1008 | C14: Meera Nair | D14: West | E14: Pen | F14: 18 | G14: 10 | H14: =PRODUCT('Q6'!$F14*'Q6'!$G14) -> 180 | I14: 15-01-2024
B15: 1009 | C15: Anjali Rao | D15: North | E15: Marker | F15: 22 | G15: 25 | H15: =PRODUCT('Q6'!$F15*'Q6'!$G15) -> 550 | I15: 17-01-2024
B16: 1010 | C16: Manoj Das | D16: South | E16: Notebook | F16: 8 | G16: 50 | H16: =PRODUCT('Q6'!$F16*'Q6'!$G16) -> 400 | I16: 18-01-2024
B17: 1011 | C17: Ritika Sen | D17: East | E17: Pencil | F17: 40 | G17: 5 | H17: =PRODUCT('Q6'!$F17*'Q6'!$G17) -> 200 | I17: 19-01-2024
B18: 1012 | C18: Karan Malhotra | D18: West | E18: Eraser | F18: 35 | G18: 8 | H18: =PRODUCT('Q6'!$F18*'Q6'!$G18) -> 280 | I18: 20-01-2024
B19: 1013 | C19: Aryan Joshi | D19: North | E19: Notebook | F19: 14 | G19: 50 | H19: =PRODUCT('Q6'!$F19*'Q6'!$G19) -> 700 | I19: 22-01-2024
B20: 1014 | C20: Divya Kapoor | D20: South | E20: Pen | F20: 28 | G20: 10 | H20: =PRODUCT('Q6'!$F20*'Q6'!$G20) -> 280 | I20: 23-01-2024
B21: 1015 | C21: Sahil Arora | D21: East | E21: Marker | F21: 12 | G21: 25 | H21: =PRODUCT('Q6'!$F21*'Q6'!$G21) -> 300 | I21: 24-01-2024
B22: 1016 | C22: Muskan Jain | D22: West | E22: Pencil | F22: 25 | G22: 5 | H22: =PRODUCT('Q6'!$F22*'Q6'!$G22) -> 125 | I22: 26-01-2024
B23: 1017 | C23: Rohan Gupta | D23: North | E23: Eraser | F23: 20 | G23: 8 | H23: =PRODUCT('Q6'!$F23*'Q6'!$G23) -> 160 | I23: 28-01-2024
B24: 1018 | C24: Nidhi Sharma | D24: South | E24: Notebook | F24: 10 | G24: 50 | H24: =PRODUCT('Q6'!$F24*'Q6'!$G24) -> 500 | I24: 29-01-2024
B25: 1019 | C25: Tarun Verma | D25: East | E25: Pen | F25: 15 | G25: 10 | H25: =PRODUCT('Q6'!$F25*'Q6'!$G25) -> 150 | I25: 30-01-2024
B26: 1020 | C26: Simran Kaur | D26: West | E26: Marker | F26: 18 | G26: 25 | H26: =PRODUCT('Q6'!$F26*'Q6'!$G26) -> 450 | I26: 45293
B27: 1021 | C27: Deepak Rao | D27: North | E27: Notebook | F27: 9 | G27: 50 | H27: =PRODUCT('Q6'!$F27*'Q6'!$G27) -> 450 | I27: 45324
B28: 1022 | C28: Payal Mehta | D28: South | E28: Pencil | F28: 35 | G28: 5 | H28: =PRODUCT('Q6'!$F28*'Q6'!$G28) -> 175 | I28: 45353
B29: 1023 | C29: Aditya Singh | D29: East | E29: Eraser | F29: 30 | G29: 8 | H29: =PRODUCT('Q6'!$F29*'Q6'!$G29) -> 240 | I29: 45384
B30: 1024 | C30: Shreya Nair | D30: West | E30: Notebook | F30: 11 | G30: 50 | H30: =PRODUCT('Q6'!$F30*'Q6'!$G30) -> 550 | I30: 45445
B31: 1025 | C31: Sanjay Kumar | D31: North | E31: Pen | F31: 14 | G31: 10 | H31: =PRODUCT('Q6'!$F31*'Q6'!$G31) -> 140 | I31: 45475
B32: 1026 | C32: Aarti Sharma | D32: South | E32: Marker | F32: 16 | G32: 25 | H32: =PRODUCT('Q6'!$F32*'Q6'!$G32) -> 400 | I32: 45506
B33: 1027 | C33: Rajesh Patel | D33: East | E33: Pencil | F33: 22 | G33: 5 | H33: =PRODUCT('Q6'!$F33*'Q6'!$G33) -> 110 | I33: 45537
B34: 1028 | C34: Preeti Joshi | D34: West | E34: Eraser | F34: 27 | G34: 8 | H34: =PRODUCT('Q6'!$F34*'Q6'!$G34) -> 216 | I34: 45567
B35: 1029 | C35: Anurag Mishra | D35: North | E35: Notebook | F35: 13 | G35: 50 | H35: =PRODUCT('Q6'!$F35*'Q6'!$G35) -> 650 | I35: 45628
B36: 1030 | C36: Sanya Kapoor | D36: South | E36: Pen | F36: 32 | G36: 10 | H36: =PRODUCT('Q6'!$F36*'Q6'!$G36) -> 320 | I36: 13-02-2024
B37: 1031 | C37: Harsh Yadav | D37: East | E37: Marker | F37: 10 | G37: 25 | H37: =PRODUCT('Q6'!$F37*'Q6'!$G37) -> 250 | I37: 14-02-2024
B38: 1032 | C38: Kajal Rani | D38: West | E38: Pencil | F38: 18 | G38: 5 | H38: =PRODUCT('Q6'!$F38*'Q6'!$G38) -> 90 | I38: 16-02-2024
B39: 1033 | C39: Varun Sharma | D39: North | E39: Eraser | F39: 22 | G39: 8 | H39: =PRODUCT('Q6'!$F39*'Q6'!$G39) -> 176 | I39: 17-02-2024
B40: 1034 | C40: Swati Arora | D40: South | E40: Notebook | F40: 17 | G40: 50 | H40: =PRODUCT('Q6'!$F40*'Q6'!$G40) -> 850 | I40: 18-02-2024
B41: 1035 | C41: Akhil Jain | D41: East | E41: Pen | F41: 19 | G41: 10 | H41: =PRODUCT('Q6'!$F41*'Q6'!$G41) -> 190 | I41: 19-02-2024
B42: 1036 | C42: Priyanka Das | D42: West | E42: Marker | F42: 15 | G42: 25 | H42: =PRODUCT('Q6'!$F42*'Q6'!$G42) -> 375 | I42: 21-02-2024
B43: 1037 | C43: Ravi Nair | D43: North | E43: Pencil | F43: 28 | G43: 5 | H43: =PRODUCT('Q6'!$F43*'Q6'!$G43) -> 140 | I43: 22-02-2024
B44: 1038 | C44: Komal Singh | D44: South | E44: Eraser | F44: 24 | G44: 8 | H44: =PRODUCT('Q6'!$F44*'Q6'!$G44) -> 192 | I44: 23-02-2024
...

Sheet Q7
B2: Create a column chart showing total sales by product.
B6: OrderID | C6: CustomerName | D6: Region | E6: Product | F6: Quantity | G6: UnitPrice | H6: Total Sales | I6: OrderDate | M6: Product | N6: sales
B7: 1001 | C7: Amit Sharma | D7: North | E7: Notebook | F7: 10 | G7: 50 | H7: =PRODUCT('Q7'!$F7*'Q7'!$G7) -> 500 | I7: 45413 | M7: Notebook | N7: =SUMIFS('Q7'!$H$7:$H$56,'Q7'!$E$7:$E$56,'Q7'!$M7) -> 7550
B8: 1002 | C8: Neha Verma | D8: South | E8: Pen | F8: 20 | G8: 10 | H8: =PRODUCT('Q7'!$F8*'Q7'!$G8) -> 200 | I8: 45444 | M8: Pen | N8: =SUMIFS('Q7'!$H$7:$H$56,'Q7'!$E$7:$E$56,'Q7'!$M8) -> 2180
B9: 1003 | C9: Rahul Singh | D9: East | E9: Marker | F9: 15 | G9: 25 | H9: =PRODUCT('Q7'!$F9*'Q7'!$G9) -> 375 | I9: 45474 | M9: Marker | N9: =SUMIFS('Q7'!$H$7:$H$56,'Q7'!$E$7:$E$56,'Q7'!$M9) -> 3650
B10: 1004 | C10: Pooja Mehta | D10: West | E10: Notebook | F10: 5 | G10: 50 | H10: =PRODUCT('Q7'!$F10*'Q7'!$G10) -> 250 | I10: 45505 | M10: Pencil | N10: =SUMIFS('Q7'!$H$7:$H$56,'Q7'!$E$7:$E$56,'Q7'!$M10) -> 1235
B11: 1005 | C11: Ankit Jain | D11: North | E11: Pencil | F11: 30 | G11: 5 | H11: =PRODUCT('Q7'!$F11*'Q7'!$G11) -> 150 | I11: 45566 | M11: Eraser | N11: =SUMIFS('Q7'!$H$7:$H$56,'Q7'!$E$7:$E$56,'Q7'!$M11) -> 1928
B12: 1006 | C12: Sneha Patel | D12: South | E12: Notebook | F12: 12 | G12: 50 | H12: =PRODUCT('Q7'!$F12*'Q7'!$G12) -> 600 | I12: 45597 | M12: Total | N12: =SUM(N7:N11) -> 16543
B13: 1007 | C13: Vikas Gupta | D13: East | E13: Eraser | F13: 25 | G13: 8 | H13: =PRODUCT('Q7'!$F13*'Q7'!$G13) -> 200 | I13: 13-01-2024 | L13: using sumifs I have extracted all the values from main table
B14: 1008 | C14: Meera Nair | D14: West | E14: Pen | F14: 18 | G14: 10 | H14: =PRODUCT('Q7'!$F14*'Q7'!$G14) -> 180 | I14: 15-01-2024
B15: 1009 | C15: Anjali Rao | D15: North | E15: Marker | F15: 22 | G15: 25 | H15: =PRODUCT('Q7'!$F15*'Q7'!$G15) -> 550 | I15: 17-01-2024
B16: 1010 | C16: Manoj Das | D16: South | E16: Notebook | F16: 8 | G16: 50 | H16: =PRODUCT('Q7'!$F16*'Q7'!$G16) -> 400 | I16: 18-01-2024
B17: 1011 | C17: Ritika Sen | D17: East | E17: Pencil | F17: 40 | G17: 5 | H17: =PRODUCT('Q7'!$F17*'Q7'!$G17) -> 200 | I17: 19-01-2024
B18: 1012 | C18: Karan Malhotra | D18: West | E18: Eraser | F18: 35 | G18: 8 | H18: =PRODUCT('Q7'!$F18*'Q7'!$G18) -> 280 | I18: 20-01-2024
B19: 1013 | C19: Aryan Joshi | D19: North | E19: Notebook | F19: 14 | G19: 50 | H19: =PRODUCT('Q7'!$F19*'Q7'!$G19) -> 700 | I19: 22-01-2024
B20: 1014 | C20: Divya Kapoor | D20: South | E20: Pen | F20: 28 | G20: 10 | H20: =PRODUCT('Q7'!$F20*'Q7'!$G20) -> 280 | I20: 23-01-2024
B21: 1015 | C21: Sahil Arora | D21: East | E21: Marker | F21: 12 | G21: 25 | H21: =PRODUCT('Q7'!$F21*'Q7'!$G21) -> 300 | I21: 24-01-2024
B22: 1016 | C22: Muskan Jain | D22: West | E22: Pencil | F22: 25 | G22: 5 | H22: =PRODUCT('Q7'!$F22*'Q7'!$G22) -> 125 | I22: 26-01-2024
B23: 1017 | C23: Rohan Gupta | D23: North | E23: Eraser | F23: 20 | G23: 8 | H23: =PRODUCT('Q7'!$F23*'Q7'!$G23) -> 160 | I23: 28-01-2024
B24: 1018 | C24: Nidhi Sharma | D24: South | E24: Notebook | F24: 10 | G24: 50 | H24: =PRODUCT('Q7'!$F24*'Q7'!$G24) -> 500 | I24: 29-01-2024
B25: 1019 | C25: Tarun Verma | D25: East | E25: Pen | F25: 15 | G25: 10 | H25: =PRODUCT('Q7'!$F25*'Q7'!$G25) -> 150 | I25: 30-01-2024
B26: 1020 | C26: Simran Kaur | D26: West | E26: Marker | F26: 18 | G26: 25 | H26: =PRODUCT('Q7'!$F26*'Q7'!$G26) -> 450 | I26: 45293
B27: 1021 | C27: Deepak Rao | D27: North | E27: Notebook | F27: 9 | G27: 50 | H27: =PRODUCT('Q7'!$F27*'Q7'!$G27) -> 450 | I27: 45324
B28: 1022 | C28: Payal Mehta | D28: South | E28: Pencil | F28: 35 | G28: 5 | H28: =PRODUCT('Q7'!$F28*'Q7'!$G28) -> 175 | I28: 45353
B29: 1023 | C29: Aditya Singh | D29: East | E29: Eraser | F29: 30 | G29: 8 | H29: =PRODUCT('Q7'!$F29*'Q7'!$G29) -> 240 | I29: 45384
B30: 1024 | C30: Shreya Nair | D30: West | E30: Notebook | F30: 11 | G30: 50 | H30: =PRODUCT('Q7'!$F30*'Q7'!$G30) -> 550 | I30: 45445
B31: 1025 | C31: Sanjay Kumar | D31: North | E31: Pen | F31: 14 | G31: 10 | H31: =PRODUCT('Q7'!$F31*'Q7'!$G31) -> 140 | I31: 45475
B32: 1026 | C32: Aarti Sharma | D32: South | E32: Marker | F32: 16 | G32: 25 | H32: =PRODUCT('Q7'!$F32*'Q7'!$G32) -> 400 | I32: 45506
B33: 1027 | C33: Rajesh Patel | D33: East | E33: Pencil | F33: 22 | G33: 5 | H33: =PRODUCT('Q7'!$F33*'Q7'!$G33) -> 110 | I33: 45537
B34: 1028 | C34: Preeti Joshi | D34: West | E34: Eraser | F34: 27 | G34: 8 | H34: =PRODUCT('Q7'!$F34*'Q7'!$G34) -> 216 | I34: 45567
B35: 1029 | C35: Anurag Mishra | D35: North | E35: Notebook | F35: 13 | G35: 50 | H35: =PRODUCT('Q7'!$F35*'Q7'!$G35) -> 650 | I35: 45628
B36: 1030 | C36: Sanya Kapoor | D36: South | E36: Pen | F36: 32 | G36: 10 | H36: =PRODUCT('Q7'!$F36*'Q7'!$G36) -> 320 | I36: 13-02-2024
B37: 1031 | C37: Harsh Yadav | D37: East | E37: Marker | F37: 10 | G37: 25 | H37: =PRODUCT('Q7'!$F37*'Q7'!$G37) -> 250 | I37: 14-02-2024
B38: 1032 | C38: Kajal Rani | D38: West | E38: Pencil | F38: 18 | G38: 5 | H38: =PRODUCT('Q7'!$F38*'Q7'!$G38) -> 90 | I38: 16-02-2024
B39: 1033 | C39: Varun Sharma | D39: North | E39: Eraser | F39: 22 | G39: 8 | H39: =PRODUCT('Q7'!$F39*'Q7'!$G39) -> 176 | I39: 17-02-2024
B40: 1034 | C40: Swati Arora | D40: South | E40: Notebook | F40: 17 | G40: 50 | H40: =PRODUCT('Q7'!$F40*'Q7'!$G40) -> 850 | I40: 18-02-2024
B41: 1035 | C41: Akhil Jain | D41: East | E41: Pen | F41: 19 | G41: 10 | H41: =PRODUCT('Q7'!$F41*'Q7'!$G41) -> 190 | I41: 19-02-2024
B42: 1036 | C42: Priyanka Das | D42: West | E42: Marker | F42: 15 | G42: 25 | H42: =PRODUCT('Q7'!$F42*'Q7'!$G42) -> 375 | I42: 21-02-2024
B43: 1037 | C43: Ravi Nair | D43: North | E43: Pencil | F43: 28 | G43: 5 | H43: =PRODUCT('Q7'!$F43*'Q7'!$G43) -> 140 | I43: 22-02-2024
B44: 1038 | C44: Komal Singh | D44: South | E44: Eraser | F44: 24 | G44: 8 | H44: =PRODUCT('Q7'!$F44*'Q7'!$G44) -> 192 | I44: 23-02-2024
...

Sheet Q8
B2: Insert a line chart showing daily sales trend.
B6: OrderID | C6: CustomerName | D6: Region | E6: Product | F6: Quantity | G6: UnitPrice | H6: Total Sales | I6: OrderDate | M6: Order Date | N6: Total Sales
B7: 1001 | C7: Amit Sharma | D7: North | E7: Notebook | F7: 10 | G7: 50 | H7: =PRODUCT('Q8'!$F7*'Q8'!$G7) -> 500 | I7: 45413 | M7: 45413 | N7: =PRODUCT('Q8'!$F7*'Q8'!$G7) -> 500
B8: 1002 | C8: Neha Verma | D8: South | E8: Pen | F8: 20 | G8: 10 | H8: =PRODUCT('Q8'!$F8*'Q8'!$G8) -> 200 | I8: 45444 | M8: 45444 | N8: =PRODUCT('Q8'!$F8*'Q8'!$G8) -> 200
B9: 1003 | C9: Rahul Singh | D9: East | E9: Marker | F9: 15 | G9: 25 | H9: =PRODUCT('Q8'!$F9*'Q8'!$G9) -> 375 | I9: 45474 | M9: 45474 | N9: =PRODUCT('Q8'!$F9*'Q8'!$G9) -> 375
B10: 1004 | C10: Pooja Mehta | D10: West | E10: Notebook | F10: 5 | G10: 50 | H10: =PRODUCT('Q8'!$F10*'Q8'!$G10) -> 250 | I10: 45505 | M10: 45505 | N10: =PRODUCT('Q8'!$F10*'Q8'!$G10) -> 250
B11: 1005 | C11: Ankit Jain | D11: North | E11: Pencil | F11: 30 | G11: 5 | H11: =PRODUCT('Q8'!$F11*'Q8'!$G11) -> 150 | I11: 45566 | M11: 45566 | N11: =PRODUCT('Q8'!$F11*'Q8'!$G11) -> 150
B12: 1006 | C12: Sneha Patel | D12: South | E12: Notebook | F12: 12 | G12: 50 | H12: =PRODUCT('Q8'!$F12*'Q8'!$G12) -> 600 | I12: 45597 | M12: 45597 | N12: =PRODUCT('Q8'!$F12*'Q8'!$G12) -> 600
B13: 1007 | C13: Vikas Gupta | D13: East | E13: Eraser | F13: 25 | G13: 8 | H13: =PRODUCT('Q8'!$F13*'Q8'!$G13) -> 200 | I13: 45304 | M13: 45304 | N13: =PRODUCT('Q8'!$F13*'Q8'!$G13) -> 200
B14: 1008 | C14: Meera Nair | D14: West | E14: Pen | F14: 18 | G14: 10 | H14: =PRODUCT('Q8'!$F14*'Q8'!$G14) -> 180 | I14: 45306 | M14: 45306 | N14: =PRODUCT('Q8'!$F14*'Q8'!$G14) -> 180
B15: 1009 | C15: Anjali Rao | D15: North | E15: Marker | F15: 22 | G15: 25 | H15: =PRODUCT('Q8'!$F15*'Q8'!$G15) -> 550 | I15: 45308 | M15: 45308 | N15: =PRODUCT('Q8'!$F15*'Q8'!$G15) -> 550
B16: 1010 | C16: Manoj Das | D16: South | E16: Notebook | F16: 8 | G16: 50 | H16: =PRODUCT('Q8'!$F16*'Q8'!$G16) -> 400 | I16: 45309 | M16: 45309 | N16: =PRODUCT('Q8'!$F16*'Q8'!$G16) -> 400
B17: 1011 | C17: Ritika Sen | D17: East | E17: Pencil | F17: 40 | G17: 5 | H17: =PRODUCT('Q8'!$F17*'Q8'!$G17) -> 200 | I17: 45310 | M17: 45310 | N17: =PRODUCT('Q8'!$F17*'Q8'!$G17) -> 200
B18: 1012 | C18: Karan Malhotra | D18: West | E18: Eraser | F18: 35 | G18: 8 | H18: =PRODUCT('Q8'!$F18*'Q8'!$G18) -> 280 | I18: 45311 | M18: 45311 | N18: =PRODUCT('Q8'!$F18*'Q8'!$G18) -> 280
... B56: 1050 | C56: Vivek Malhotra | D56: South | E56: Pen | F56: 25 | G56: 10 | H56: =PRODUCT('Q8'!$F56*'Q8'!$G56) -> 250 | I56: 45507 | M56: 45507 | N56: =PRODUCT('Q8'!$F56*'Q8'!$G56) -> 250
