Workbook

Sheet Assignment

Sheet Q1
B3: Q1.What is data cleaning, and why is it important in data analysis?
B5: Ans:
B6: Data cleaning is a process of extracting errors and inaccuracies , inconsistencies in raw data so that data becomes workable or accurate
B7: imagine you are cooking, your vegetables are dirty ,or some cut wrongly , some are not eatable so washing them ,throwing away bad ones and cutting some properly gives better food quality
B9: Why it is important for data analysis?
B11: Ensures accurate results:
B13: data cleaning ensures accurate data makes our analysis top notch and trustworthy
B15: Prevent wrong conclusions and wrong insights
B17: it makes sure that user is not sending wrong data, assures clean data and right insights
B20: Improves quality of report and dashboards
B22: Makes data consistent and easy to analyse
A25: a. What are the potential consequences of analyzing unclean or messy data?
B27: Wrong data & wrong information as a analyst its worst thing to happen
B29: Errors in calculation and reports
B31: Reduce credibility of data and can make a bad impression of data analyst
A34: b.Explain the common steps involved in cleaning and organizing data.
B36: Removing errors like duplicate values
B38: Recorrecting missing value data
B40: correcting calculations and spelling mistakes
B42: using standard formats like dates,textcases,numbers
B44: Remove extra spaces from cells
B46: organise data properly using sorting

Sheet Q2
B2: How would you sort the following dataset first by "Department" (A-Z) and then by "Salary" (Largest to Smallest)? Write a step-by-step approach.
G7: Step 1
B8: Employee | C8: Department | D8: Salary
B9: Sonu | C9: IT | D9: 4000
B10: Pranav | C10: HR | D10: 5000
B11: Rahul | C11: IT | D11: 2500
B14: To sort dataset by department(A-Z)
B15: We have to use Sort option from data and select (A-Z) Ascending
B17: To sort dataset by Salary(largest-smallest) | H17: Step 2
B18: largest to smallest means order should be in ascending order
B19: using add level , we can sort salary according to required order
B22: Employee | C22: Department | D22: Salary
B23: Pranav | C23: HR | D23: 5000
B24: Sonu | C24: IT | D24: 4000
B25: Rahul | C25: IT | D25: 2500
B28: Here, Table is sorted by department in (A-Z ) order
B29: and Salary is sorted by department in (largest-smallest ) order

Sheet Q3
B2: Q3.Explain the use of text functions such as TRIM , LEFT, RIGHT, MID, and CONCAT in data cleaning.
B8: TRIM() | L8: NAME | M8: TRIM | N8: LEFT | O8: RIGHT | P8: MID | Q8: CONCAT
L9: Abhijeet Nalavade | M9: =TRIM('Q3'!$L9) -> Abhijeet Nalavade
B10: TRIM function removes all extra spaces from a text except single spaces between words | L10: Rahul patil | M10: =TRIM('Q3'!$L10) -> Rahul patil
G11: NAME | H11: TRIM | L11: Akshay Kulkarni | M11: =TRIM('Q3'!$L11) -> Akshay Kulkarni
G12: Abhijeet Nalavade | H12: =TRIM(G12) -> Abhijeet Nalavade | L12: sanket Jadhav | M12: =TRIM('Q3'!$L12) -> sanket Jadhav
G13: Rahul patil | H13: =TRIM(G13) -> Rahul patil | L13: Mandar Bhandari | M13: =TRIM('Q3'!$L13) -> Mandar Bhandari
G14: Akshay Kulkarni | H14: =TRIM(G14) -> Akshay Kulkarni
G15: sanket Jadhav | H15: =TRIM(G15) -> sanket Jadhav
G16: Mandar Bhandari | H16: =TRIM(G16) -> Mandar Bhandari
B19: LEFT()
B21: LEFT function extracts a specified no of characters from a left side of a text string
B22: Lets say I want first 3 characters of every first name from left | G22: NAME | H22: LEFT
G23: Abhijeet Nalavade | H23: =LEFT(G23,3) -> Abh
G24: Rahul patil | H24: =LEFT(G24,3) -> Rah
G25: Akshay Kulkarni | H25: =LEFT(G25,3) -> Aks
G26: sanket Jadhav | H26: =LEFT(G26,3) -> san
G27: Mandar Bhandari | H27: =LEFT(G27,3) -> Man
B29: RIGHT()
B31: RIGHT function extracts a specified no of characters from a right side of a text string
B32: Lets say I want last 3 characters of every last name from rightmost side | G32: NAME | H32: RIGHT
G33: Abhijeet Nalavade | H33: =RIGHT(G33,3) -> ade
G34: Rahul patil | H34: =RIGHT(G34,3) -> til
G35: Akshay Kulkarni | H35: =RIGHT(G35,3) -> rni
G36: sanket Jadhav | H36: =RIGHT(G36,3) -> hav
G37: Mandar Bhandari | H37: =RIGHT(G37,3) -> ari
B40: MID()
B42: MID function extracts text from the middle of a string from a specified position and for a given no of characters
B43: lets say I want mid characters on first name using mid I can extract | G43: NAME | H43: MID
B44: here, mid functions asks for Text,characters_num,num_of_characters | G44: Abhijeet Nalavade | H44: =MID(G44,4,4) -> ijee
G45: Rahul patil | H45: =MID(G45,4,4) -> ul
G46: Akshay Kulkarni | H46: =MID(G46,4,4) -> hay
G47: sanket Jadhav | H47: =MID(G47,4,4) -> ket
G48: Mandar Bhandari | H48: =MID(G48,4,4) -> dar
B51: CONCAT()
B53: CONCAT function joins two or more text value into single text string
B55: here, we will add two name (first & last name) to make it a one string value
G56: FIRST NAME | H56: LAST NAME | I56: CONCATENATE
B57: We can also add space using (" ") in between formula | G57: Abhijeet | H57: Nalavade | I57: =CONCAT(G57,H57) -> Abhijeet Nalavade
B58: We can also add any symbol ("$") in between formula | G58: Rahul | H58: patil | I58: =CONCAT(G58,H58) -> Rahul patil
...

Sheet Q4
B2: Q4.What is the role of date functions like TODAY in managing datasets?
B6: TODAY() is a date function in excel that automatically returns the current date as per the sytem, it will change as per time changes
B7: this function can also used to find number of days passed, age & duration.
C9: FUNCTION | D9: DATE
C10: TODAY | D10: =TODAY() -> 46029
C12: This date will automatically change tomorrow
B15: TODAY(_) play an imp role in managing dataset by automatically returning the current system date. it helps in calculating the no. of days passed or remaining
B16: ,finding age,tracking duration,deadlines

Sheet Q5
B2: Apply Data Validation to restrict Quantity values to only whole numbers between 1 and 10.
B8: Customer Name | C8: Product Name | D8: Category | E8: Quantity | F8: Unit Price ($) | H8: Step 1 | I8: select all the cells where we want to apply data validation
B9: Jane Smith | C9: Shoes | D9: Electronics | E9: 1 | F9: 81
B10: Isabella Moore | C10: Laptop | D10: Electronics | E10: 2 | F10: 121 | H10: Step 2 | I10: Go to data tab = under Data tools = select data validation
B11: Daniel Davis | C11: Sofa | D11: Clothing | E11: 3 | F11: 239
B12: Alex Moore | C12: Shoes | D12: Electronics | E12: 4 | F12: 500
B13: Michael Johnson | C13: Table Lamp | D13: Home Decor | E13: 5 | F13: 423
B14: Daniel Johnson | C14: Backpack | D14: Electronics | E14: 6 | F14: 160
B15: Isabella Davis | C15: Headphones | D15: Electronics | E15: 7 | F15: 348
B16: Jane Davis | C16: Headphones | D16: Electronics | E16: 8 | F16: 152
B17: Alex Wilson | C17: T-shirt | D17: Electronics | E17: 9 | F17: 369
B19: google doc sheet not showing input messages properly , it was showing in excel sheet
H22: Step 3 | I22: 1.under data validation = go to settings = under validation criteria - select whole number
I23: 2.select between = choose 1 as mimimum & 10 as maximum value as per question
B26: A.Configure an input message that appears when a user selects a cell in the "Quantity" column explaining "Please enter a whole number between 1 and 10.
B27: B.Set up an error alert message that triggers if the user enters a number less than 1 or greater than 10, showing "Invalid input! The quantity must be a whole number between 1 and 10.
H31: step 4 | I31: We can include input message it helps user to see what criteria is needed in this column
I32: We can also include error alert after user fails to oblige to criteria given with error alert
B33: This is an input message showing in excel sheet
B34: since in docs file input message not showing

Sheet Q6
B2: 6.Understand and apply fundamental text functions like LEFT, RIGHT, MID, and LEN
B4: 1) Extract the first 5 characters from the string "ExcelTipsAreGreat" using the LEFT function.
B6: Ans: | D6: (from left side )
C7: ExcelTipsAreGreat | D7: =LEFT(C7,5) -> Excel | E7: using LEFT () we can extract number of selected characters from leftmost side
B10: 2) Extract the last 4 characters from "DataAnalysis.xlsx" using the RIGHT function
D12: (from right side )
C13: DataAnalysis.xlsx | D13: =RIGHT(C13,4) -> xlsx | E13: using RIGHT() we can extract number of selected characters from rightmost side
B15: 3) Extract the substring "Tips" from "ExcelTipsAreGreat" using the MID function
C17: ExcelTipsAreGreat | D17: =MID(C17,6,4) -> Tips | E17: using MID() we can extract number of selected characters from MIDDLE
B20: 4) Count the total number of characters in the string "Hello World!" using the LEN function.
C22: Hello World! | D22: =LEN(C22) -> 12 | E22: using LEN() we can count number of characters including all spaces,comma,symbols etc
B25: 5) Create a formula to extract the middle 6 characters from "12345-67890-ABCDE"
C27: 12345-67890-ABCDE | D27: =MID(C27,7,6) -> 67890-
B29: we can use MID() function to extract MIDDLE values.
B31: 12345- = 6 | C31: upper
B32: 67890- = 6 | C32: middle
B33: ABCDE = 5 | C33: last

Sheet Q7
B2: 7.Understand how to combine text using CONCAT, TEXTJOIN, and the & operator.
B4: A) Use CONCAT to combine "Hello" and "World" with a space in between.
C6: Hello | D6: World | E6: =CONCATENATE(C6," ",D6) -> Hello World
B8: B) Combine "Apple", "Banana", and "Cherry" into a single string separated by commas using TEXTJOIN.
C11: Apple | D11: Banana | E11: Cherry
E13: =TEXTJOIN(", ",TRUE,C11:E11) -> Apple, Banana, Cherry
B16: C) Use the & operator to create the string "2025: Excel Functions" by combining "2025", ": ", and "Excel Functions".
E18: "&"operation joins multiple text into one string
C20: 2025: Excel Functions
G21: used formula
D22: ="2025"&": "&"Excel Functions" -> 2025: Excel Functions | G22: "2025"&": "&"Excel Functions"
B25: D) Create a comma-separated list from the range A1:A5 using TEXTJOIN
B29: Customer Name | C29: Product Name | D29: Category | E29: Quantity | F29: Unit Price ($) | H29: =TEXTJOIN(", ",TRUE,B30:B34) -> Jane Smith, Isabella Moore, Daniel Davis, Alex Moore, Michael Johnson
B30: Jane Smith | C30: Shoes | D30: Electronics | E30: 1 | F30: 81
B31: Isabella Moore | C31: Laptop | D31: Electronics | E31: 2 | F31: 121
B32: Daniel Davis | C32: Sofa | D32: Clothing | E32: 3 | F32: 239 | I32: used formula
B33: Alex Moore | C33: Shoes | D33: Electronics | E33: 4 | F33: 500 | I33: TEXTJOIN(", ",TRUE,B30:B34)
B34: Michael Johnson | C34: Table Lamp | D34: Home Decor | E34: 5 | F34: 423
B35: Daniel Johnson | C35: Backpack | D35: Electronics | E35: 6 | F35: 160
B36: Isabella Davis | C36: Headphones | D36: Electronics | E36: 7 | F36: 348
B37: Jane Davis | C37: Headphones | D37: Electronics | E37: 8 | F37: 152
B38: Alex Wilson | C38: T-shirt | D38: Electronics | E38: 9 | F38: 369
B42: E) Combine first names in column A with last names in column B to create full names in column C.
B44: To add full name using concatenate we can add first name & last name
B45: METHOD 1
B46: Customer Name | C46: Product Name | D46: First Name | E46: Last Name | F46: Full Name | G46: Category | H46: Quantity | I46: Unit Price ($)
B47: Jane Smith | C47: Shoes | D47: Jane | E47: Smith | F47: =CONCATENATE(D47," ",E47) -> Jane Smith | G47: Electronics | H47: 1 | I47: 81
B48: Isabella Moore | C48: Laptop | D48: Isabella | E48: Moore | F48: =CONCATENATE(D48," ",E48) -> Isabella Moore | G48: Electronics | H48: 2 | I48: 121
B49: Daniel Davis | C49: Sofa | D49: Daniel | E49: Davis | F49: =CONCATENATE(D49," ",E49) -> Daniel Davis | G49: Clothing | H49: 3 | I49: 239
B50: Alex Moore | C50: Shoes | D50: Alex | E50: Moore | F50: =CONCATENATE(D50," ",E50) -> Alex Moore | G50: Electronics | H50: 4 | I50: 500
B51: Michael Johnson | C51: Table Lamp | D51: Michael | E51: Johnson | F51: =CONCATENATE(D51," ",E51) -> Michael Johnson | G51: Home Decor | H51: 5 | I51: 423
B52: Daniel Johnson | C52: Backpack | D52: Daniel | E52: Johnson | F52: =CONCATENATE(D52," ",E52) -> Daniel Johnson | G52: Electronics | H52: 6 | I52: 160
B53: Isabella Davis | C53: Headphones | D53: Isabella | E53: Davis | F53: =CONCATENATE(D53," ",E53) -> Isabella Davis | G53: Electronics | H53: 7 | I53: 348
B54: Jane Davis | C54: Headphones | D54: Jane | E54: Davis | F54: =CONCATENATE(D54," ",E54) -> Jane Davis | G54: Electronics | H54: 8 | I54: 152
B55: Alex Wilson | C55: T-shirt | D55: Alex | E55: Wilson | F55: =CONCATENATE(D55," ",E55) -> Alex Wilson | G55: Electronics | H55: 9 | I55: 369
B57: using Flash fill or CTRL + E we can add first name and last name
B58: just typing first name in any cell and using ctrl + E we can add all name
B60: METHOD 2
B61: Customer Name | C61: Product Name | D61: First Name | E61: Last Name | F61: Full Name | G61: Category | H61: Quantity | I61: Unit Price ($)
B62: Jane Smith | C62: Shoes | D62: =LEFT('Q7'!$B62,FIND(" ",'Q7'!$B62)-1) -> Jane | E62: =RIGHT('Q7'!$B62,LEN('Q7'!$B62)-FIND(" ",'Q7'!$B62)) -> Smith | F62: =CONCATENATE(D62," ",E62) -> Jane Smith | G62: Electronics | H62: 1 | I62: 81
...

Sheet Q8
B2: 8. Understanding TODAY() and NOW()
B4: What is the difference between TODAY() and NOW() in Excel? Provide an example of when you would use each function
B7: TODAY()
B8: TODAY() function returns the current date based on system. It only gives date nothing else
B9: also it will change date automatically according to clock this date will change tomorrow
B10: =TODAY() -> 46029
B13: NOW()
B14: NOW() function returns the current date along with current time. It gives more detail than TODAY() function
B16: =NOW() -> 46029.94
B19: lets take an example for TODAY(), assume a bank wants to apply late fees if loan emi date passed
B21: EMI due date | C21: Status
B22: 46029 | C22: =IF(B22<TODAY(),"Late fee","No late fee") -> No late fee
B24: used formula | C24: IF(B22<TODAY(),"Late fee","No late fee")
B26: lets take an example for NOW() ,assume online shopping site records the exact time when an order is placed
B28: Order Id | C28: Order date & time
B29: 11111 | C29: =NOW() -> 46029.94
B32: b.if cell A1 contains the date 2025-06-10, write a formula using TODAY() to determine how many days are left until that date
B35: DATE | C35: FORMULA
B36: 45818 | C36: =TODAY()-B36 -> 211
C38: it shows its been 211 days since day has passed from todays days, it might show different number for mentors since they might check this assigment after some days
B42: C. Write an Excel formula using NOW() to display the current date and time in the format MM/DD/YYYY HH:MM AM/PM.
B45: CURRENT DATE | C45: =NOW() -> 46029.94
C46: using customise date format changed the format to MM/DD/YYYY HH:MM AM/PM
B50: d. If a cell contains =TODAY(), what will happen when the worksheet is reopened the next day? Explain
B51: if cell contains TODAY() function the date will automatically update when the worksheet is open next day
B52: excel recalculates it every time the workbook is opened again ex. If today is 7 jan , tomorrow if opened it will show 8 jan
B55: e.You want to store a static date (today’s date) in a cell without it changing every day. What keyboard shortcut should you use?
B57: CTRL + ; | C57: This is a shorcut key which show TODAY() function directly
